<mujoco model="phonebot">
  <compiler angle="radian"/>

  <worldbody>
    <geom size="0.01425 0.02325 0.017" pos="0 -0.012 0" type="box" rgba="0.89804 0.91765 0.92941 1"/>
    <geom size="0.01425 0.02325 0.017" pos="-0.05 -0.012 0" quat="0.707107 0 -0.707107 0" type="box" rgba="0.89804 0.91765 0.92941 1"/>
    <geom size="0.01425 0.02325 0.017" pos="0.05 -0.012 0" quat="0.707107 0 0.707107 0" type="box" rgba="0.89804 0.91765 0.92941 1"/>
    <body name="l_hip_roll" pos="-0.09 0 1.30718e-08" quat="2.31079e-07 0 -0.707107 -0.707107">
      <inertial pos="0 -0.012 0" quat="0.707107 0.707107 0 0" mass="0.065" diaginertia="1.797e-05 1.611e-05 1.066e-05"/>
      <joint name="l_hip_pitch_joint" pos="0 0 0" axis="1 0 0" range="-3.14159 3.14159" actuatorfrcrange="-5 5"/>
      <geom size="0.01425 0.02325 0.017" pos="0 -0.012 0" type="box" rgba="0.89804 0.91765 0.92941 1"/>
      <body name="l_hip_roll_joint_frame">
        <inertial pos="0 -0.0118182 -0.0590909" quat="0.592284 0.805729 0 0" mass="0.066" diaginertia="2.16773e-05 1.64935e-05 1.40038e-05"/>
        <joint name="l_hip_roll_joint" pos="0 0 0" axis="0 0 1" range="-3.14159 3.14159" actuatorfrcrange="-5 5"/>
        <geom size="0.01425 0.02325 0.017" pos="0 -0.06 -0.012" quat="0.707107 0.707107 0 0" type="box" rgba="0.89804 0.91765 0.92941 1"/>
        <body name="l_hip_thigh_joint_frame" pos="0 -0.06 0" quat="0.707107 0.707107 0 0">
          <inertial pos="0 -0.0512121 0" quat="0.707107 0.707107 0 0" mass="0.066" diaginertia="2.0653e-05 1.8793e-05 1.068e-05"/>
          <joint name="l_hip_thigh_joint" pos="0 0 0" axis="0 0 1" range="-3.14159 3.14159" actuatorfrcrange="-5 5"/>
          <geom size="0.01425 0.02325 0.017" pos="-3.92154e-09 0 0.052" quat="0.5 -0.5 0.5 -0.5" type="box" rgba="0.89804 0.91765 0.92941 1"/>
          <body name="l_hip_calf_joint_frame" pos="0 0 0.04" quat="0.5 -0.5 0.5 -0.5">
            <inertial pos="0 0 0" mass="0.001" diaginertia="2e-08 2e-08 2e-08"/>
            <joint name="l_hip_calf_joint" pos="0 0 0" axis="0 0 1" range="-3.14159 3.14159" actuatorfrcrange="-5 5"/>
            <body name="l_ankle_pitch_joint_frame" pos="0 -0.1 0">
              <inertial pos="0.0198473 -0.0119084 6.87532e-09" quat="0.00223735 0.707103 -0.00223735 0.707103" mass="0.131" diaginertia="8.47798e-05 7.37385e-05 3.61014e-05"/>
              <joint name="l_ankle_pitch_joint" pos="0 0 0" axis="0 0 1" range="-3.14159 3.14159" actuatorfrcrange="-5 5"/>
              <geom size="0.01425 0.02325 0.017" pos="-4.15692e-09 0.012 0" quat="-1.73205e-07 0 0 1" type="box" rgba="0.89804 0.91765 0.92941 1"/>
              <geom size="0.01425 0.02325 0.017" pos="0.04 0.012 0" quat="-1.22475e-07 -0.707107 -1.22474e-07 0.707107" type="box" rgba="0.89804 0.91765 0.92941 1"/>
              <body name="l_foot" pos="1.21244e-08 -0.035 1.30718e-08" quat="-1.22475e-07 -1.22474e-07 0.707107 0.707107">
                <inertial pos="0 0 0" quat="0 0.707107 0 0.707107" mass="0.05" diaginertia="5.667e-05 4.208e-05 1.542e-05"/>
                <joint name="l_ankle_roll_joint" pos="0 0 0" axis="1 0 0" range="-3.14159 3.14159" actuatorfrcrange="-5 5"/>
                <geom size="0.05 0.03 0.005" type="box" rgba="0.89804 0.91765 0.92941 1"/>
              </body>
            </body>
          </body>
        </body>
      </body>
    </body>
    <body name="r_hip_roll" pos="0.09 0 1.30718e-08" quat="2.31079e-07 0 0.707107 0.707107">
      <inertial pos="0 -0.012 0" quat="0.707107 0.707107 0 0" mass="0.065" diaginertia="1.797e-05 1.611e-05 1.066e-05"/>
      <joint name="r_hip_pitch_joint" pos="0 0 0" axis="-1 0 0" range="-3.14159 3.14159" actuatorfrcrange="-5 5"/>
      <geom size="0.01425 0.02325 0.017" pos="0 -0.012 0" type="box" rgba="0.89804 0.91765 0.92941 1"/>
      <body name="r_hip_roll_joint_frame">
        <inertial pos="0 -0.0118182 -0.0590909" quat="0.592284 0.805729 0 0" mass="0.066" diaginertia="2.16773e-05 1.64935e-05 1.40038e-05"/>
        <joint name="r_hip_roll_joint" pos="0 0 0" axis="0 0 1" range="-3.14159 3.14159" actuatorfrcrange="-5 5"/>
        <geom size="0.01425 0.02325 0.017" pos="0 -0.06 -0.012" quat="0.707107 0.707107 0 0" type="box" rgba="0.89804 0.91765 0.92941 1"/>
        <body name="r_hip_thigh_joint_frame" pos="0 -0.06 0" quat="0.707107 0.707107 0 0">
          <inertial pos="0 -0.0512121 0" quat="0.707107 0.707107 0 0" mass="0.066" diaginertia="2.0653e-05 1.8793e-05 1.068e-05"/>
          <joint name="r_hip_thigh_joint" pos="0 0 0" axis="0 0 1" range="-3.14159 3.14159" actuatorfrcrange="-5 5"/>
          <geom size="0.01425 0.02325 0.017" pos="3.92154e-09 0 0.052" quat="0.5 -0.5 -0.5 0.5" type="box" rgba="0.89804 0.91765 0.92941 1"/>
          <body name="r_hip_calf_joint_frame" pos="0 0 0.04" quat="0.5 -0.5 -0.5 0.5">
            <inertial pos="0 0 0" mass="0.001" diaginertia="2e-08 2e-08 2e-08"/>
            <joint name="r_hip_calf_joint" pos="0 0 0" axis="0 0 1" range="-3.14159 3.14159" actuatorfrcrange="-5 5"/>
            <body name="r_ankle_pitch_joint_frame" pos="0 -0.1 0">
              <inertial pos="-0.0198473 -0.0119084 6.87532e-09" quat="-0.00223735 0.707103 0.00223735 0.707103" mass="0.131" diaginertia="8.47798e-05 7.37385e-05 3.61014e-05"/>
              <joint name="r_ankle_pitch_joint" pos="0 0 0" axis="0 0 1" range="-3.14159 3.14159" actuatorfrcrange="-5 5"/>
              <geom size="0.01425 0.02325 0.017" pos="4.15692e-09 0.012 0" quat="-1.73205e-07 0 0 -1" type="box" rgba="0.89804 0.91765 0.92941 1"/>
              <geom size="0.01425 0.02325 0.017" pos="-0.04 0.012 0" quat="-1.22475e-07 -0.707107 1.22474e-07 -0.707107" type="box" rgba="0.89804 0.91765 0.92941 1"/>
              <body name="r_foot" pos="-1.21244e-08 -0.035 1.30718e-08" quat="-3.53553e-07 -1.22474e-07 -0.707107 -0.707107">
                <inertial pos="0 0 0" quat="0 0.707107 0 0.707107" mass="0.05" diaginertia="5.667e-05 4.208e-05 1.542e-05"/>
                <joint name="r_ankle_roll_joint" pos="0 0 0" axis="-1 0 0" range="-3.14159 3.14159" actuatorfrcrange="-5 5"/>
                <geom size="0.05 0.03 0.005" type="box" rgba="0.89804 0.91765 0.92941 1"/>
              </body>
            </body>
          </body>
        </body>
      </body>
    </body>
    <body name="trunk_link" pos="0 0 0.11">
      <inertial pos="0 0 0" quat="0.707107 0 0 0.707107" mass="0.3" diaginertia="0.000685 0.000565 0.000125"/>
      <joint name="base_to_trunk" pos="0 0 0" axis="0 0 1" range="-3.14159 3.14159" actuatorfrcrange="-5 5"/>
      <geom size="0.035 0.005 0.075" type="box" rgba="0.89804 0.91765 0.92941 1"/>
    </body>
  </worldbody>
</mujoco>
