<mujoco model="phonebot">
  <default>
    <default class="robot">
      <default class="motor">
        <joint />
        <motor />
        </default>
      <default class="visual">
        <geom material="visualgeom" contype="0" conaffinity="0" group="2" />
        </default>
      <default class="collision">
        <geom material="collision_material" condim="3" contype="0" conaffinity="1" priority="1" group="1" solref="0.005 1" solimp="0.99 0.999 1e-05" friction="1 0.01 0.01" />
        </default>
      </default>
    </default>
  <compiler angle="radian" />
  <asset>
    <material name="motor_gray" rgba="0.89804 0.91765 0.92941 1.0" />
    <material name="default_material" rgba="0.7 0.7 0.7 1" />
    <material name="collision_material" rgba="0.0 0.8 0.1 1.0" />
    <mesh name="XL-430_new_coordinate_on_axis.STL" file="/media/hrc/T7_UBUNTU_ONLY/Codesign_ChopstickBot_all_files/reference/xm430_motor/good_conversion_stl/XL-430_new_coordinate_on_axis.STL" scale="0.001000 0.001000 0.001000" />
    </asset>
  <worldbody>
    <body name="base_motor_link" pos="0.00000000 0.00000000 0.23999999" quat="1 0 0 0" childclass="robot">
      <freejoint name="floating_base" />
      <geom name="base_motor_link_collision" pos="0.000000 -0.012000 0.000000" quat="1.0 0.0 0.0 0.0" type="box" size="0.01425 0.02325 0.017" class="collision" />
      <geom name="base_motor_link_visual" pos="0.000000 0.000000 0.000000" quat="1.0 0.0 0.0 0.0" material="motor_gray" type="mesh" mesh="XL-430_new_coordinate_on_axis.STL" class="visual" />
      <body name="l_hip_pitch_mount" pos="-0.050000 0.000000 0.000000" quat="0.7071068967259818 0.0 -0.7071066656470943 0.0">
        <inertial pos="0.000000 0.000000 0.000000" quat="1.0 0.0 0.0 0.0" mass="0.001000" diaginertia="2e-08 2e-08 2e-08" />
        <body name="l_hip_pitch" pos="0.000000 0.000000 0.000000" quat="1.0 0.0 0.0 0.0">
          <inertial pos="0.000000 -0.012000 0.000000" quat="1.0 0.0 0.0 0.0" mass="0.065000" diaginertia="1.797e-05 1.066e-05 1.611e-05" />
          <geom name="l_hip_pitch_collision" pos="0.000000 -0.012000 0.000000" quat="1.0 0.0 0.0 0.0" type="box" size="0.01425 0.02325 0.017" class="collision" />
          <geom name="l_hip_pitch_visual" pos="0.000000 0.000000 0.000000" quat="1.0 0.0 0.0 0.0" material="motor_gray" type="mesh" mesh="XL-430_new_coordinate_on_axis.STL" class="visual" />
          <body name="l_hip_roll" pos="0.000000 0.000000 0.040000" quat="0.5000001633974483 -0.49999983660255165 -0.4999999999999733 -0.4999999999999733">
            <joint name="l_hip_pitch_joint" type="hinge" ref="0.0" class="motor" range="-3.14159 3.14159" axis="1.000000 0.000000 0.000000" />
            <site name="l_hip_pitch_joint_site" pos="0 0 0" quat="1 0 0 0" />
            <inertial pos="0.000000 -0.012000 0.000000" quat="1.0 0.0 0.0 0.0" mass="0.065000" diaginertia="1.797e-05 1.066e-05 1.611e-05" />
            <geom name="l_hip_roll_collision" pos="0.000000 -0.012000 0.000000" quat="1.0 0.0 0.0 0.0" type="box" size="0.01425 0.02325 0.017" class="collision" />
            <geom name="l_hip_roll_visual" pos="0.000000 0.000000 0.000000" quat="1.0 0.0 0.0 0.0" material="motor_gray" type="mesh" mesh="XL-430_new_coordinate_on_axis.STL" class="visual" />
            <body name="l_hip_roll_joint_frame" pos="0.000000 0.000000 0.000000" quat="1.0 0.0 0.0 0.0">
              <joint name="l_hip_roll_joint" type="hinge" ref="0.0" class="motor" range="-3.14159 3.14159" axis="0.000000 0.000000 1.000000" />
              <site name="l_hip_roll_joint_site" pos="0 0 0" quat="1 0 0 0" />
              <inertial pos="0.000000 0.000000 0.000000" quat="1.0 0.0 0.0 0.0" mass="0.001000" diaginertia="2e-08 2e-08 2e-08" />
              <body name="l_hip_thigh_joint_frame" pos="0.000000 -0.060000 0.000000" quat="1.0 0.0 0.0 0.0">
                <joint name="l_hip_thigh_joint" type="hinge" ref="0.0" class="motor" range="-3.14159 3.14159" axis="0.000000 0.000000 1.000000" />
                <site name="l_hip_thigh_joint_site" pos="0 0 0" quat="1 0 0 0" />
                <inertial pos="0.000000 0.000000 0.000000" quat="1.0 0.0 0.0 0.0" mass="0.001000" diaginertia="2e-08 2e-08 2e-08" />
                <body name="l_hip_thigh" pos="0.000000 0.000000 0.000000" quat="0.7071068967259818 0.7071066656470943 0.0 0.0">
                  <inertial pos="0.000000 -0.012000 0.000000" quat="1.0 0.0 0.0 0.0" mass="0.065000" diaginertia="1.797e-05 1.066e-05 1.611e-05" />
                  <geom name="l_hip_thigh_collision" pos="0.000000 -0.012000 0.000000" quat="1.0 0.0 0.0 0.0" type="box" size="0.01425 0.02325 0.017" class="collision" />
                  <geom name="l_hip_thigh_visual" pos="0.000000 0.000000 0.000000" quat="1.0 0.0 0.0 0.0" material="motor_gray" type="mesh" mesh="XL-430_new_coordinate_on_axis.STL" class="visual" />
                  <body name="l_hip_calf_joint_frame" pos="0.000000 0.000000 0.040000" quat="1.0 0.0 0.0 0.0">
                    <joint name="l_hip_calf_joint" type="hinge" ref="0.0" class="motor" range="-3.14159 3.14159" axis="0.000000 0.000000 1.000000" />
                    <site name="l_hip_calf_joint_site" pos="0 0 0" quat="1 0 0 0" />
                    <inertial pos="0.000000 0.000000 0.000000" quat="1.0 0.0 0.0 0.0" mass="0.001000" diaginertia="2e-08 2e-08 2e-08" />
                    <body name="l_hip_calf" pos="0.000000 0.000000 0.000000" quat="0.5000001633974483 -0.4999999999999733 0.49999983660255165 -0.4999999999999733">
                      <inertial pos="0.000000 -0.012000 0.000000" quat="1.0 0.0 0.0 0.0" mass="0.065000" diaginertia="1.797e-05 1.066e-05 1.611e-05" />
                      <geom name="l_hip_calf_collision" pos="0.000000 -0.012000 0.000000" quat="1.0 0.0 0.0 0.0" type="box" size="0.01425 0.02325 0.017" class="collision" />
                      <geom name="l_hip_calf_visual" pos="0.000000 0.000000 0.000000" quat="1.0 0.0 0.0 0.0" material="motor_gray" type="mesh" mesh="XL-430_new_coordinate_on_axis.STL" class="visual" />
                      <body name="l_ankle_pitch_joint_frame" pos="0.000000 -0.100000 0.000000" quat="1.0 0.0 0.0 0.0">
                        <joint name="l_ankle_pitch_joint" type="hinge" ref="0.0" class="motor" range="-3.14159 3.14159" axis="0.000000 0.000000 1.000000" />
                        <site name="l_ankle_pitch_joint_site" pos="0 0 0" quat="1 0 0 0" />
                        <inertial pos="0.000000 0.000000 0.000000" quat="1.0 0.0 0.0 0.0" mass="0.001000" diaginertia="2e-08 2e-08 2e-08" />
                        <body name="l_ankle_pitch" pos="0.000000 0.000000 0.000000" quat="-1.7320510330969933e-07 -0.0 0.0 0.999999999999985">
                          <inertial pos="0.000000 -0.012000 0.000000" quat="1.0 0.0 0.0 0.0" mass="0.065000" diaginertia="1.797e-05 1.066e-05 1.611e-05" />
                          <geom name="l_ankle_pitch_collision" pos="0.000000 -0.012000 0.000000" quat="1.0 0.0 0.0 0.0" type="box" size="0.01425 0.02325 0.017" class="collision" />
                          <geom name="l_ankle_pitch_visual" pos="0.000000 0.000000 0.000000" quat="1.0 0.0 0.0 0.0" material="motor_gray" type="mesh" mesh="XL-430_new_coordinate_on_axis.STL" class="visual" />
                          <body name="l_ankle_roll_joint_frame" pos="-0.040000 0.000000 0.000000" quat="1.0 0.0 0.0 0.0">
                            <joint name="l_ankle_roll_joint" type="hinge" ref="0.0" class="motor" range="-3.14159 3.14159" axis="0.000000 0.000000 1.000000" />
                            <site name="l_ankle_roll_joint_site" pos="0 0 0" quat="1 0 0 0" />
                            <inertial pos="0.000000 0.000000 0.000000" quat="1.0 0.0 0.0 0.0" mass="0.001000" diaginertia="2e-08 2e-08 2e-08" />
                            <body name="l_ankle_roll" pos="0.000000 0.000000 0.000000" quat="0.7071068967259818 0.0 0.7071066656470943 0.0">
                              <inertial pos="0.000000 -0.012000 0.000000" quat="1.0 0.0 0.0 0.0" mass="0.065000" diaginertia="1.797e-05 1.066e-05 1.611e-05" />
                              <geom name="l_ankle_roll_collision" pos="0.000000 -0.012000 0.000000" quat="1.0 0.0 0.0 0.0" type="box" size="0.01425 0.02325 0.017" class="collision" />
                              <geom name="l_ankle_roll_visual" pos="0.000000 0.000000 0.000000" quat="1.0 0.0 0.0 0.0" material="motor_gray" type="mesh" mesh="XL-430_new_coordinate_on_axis.STL" class="visual" />
                              <body name="l_foot" pos="0.000000 0.035000 0.040000" quat="0.5000001633974483 0.4999999999999733 -0.4999999999999733 0.49999983660255165">
                                <inertial pos="0.000000 0.000000 0.000000" quat="1.0 0.0 0.0 0.0" mass="0.050000" diaginertia="1.542e-05 4.208e-05 5.667e-05" />
                                <geom name="l_foot_collision" pos="0.000000 0.000000 0.000000" quat="1.0 0.0 0.0 0.0" type="box" size="0.05 0.03 0.005" class="collision" />
                                <geom name="l_foot_visual" pos="0.000000 0.000000 0.000000" quat="1.0 0.0 0.0 0.0" material="motor_gray" type="box" size="0.05 0.03 0.005" class="visual" />
                                </body>
                              </body>
                            </body>
                          </body>
                        </body>
                      </body>
                    </body>
                  </body>
                </body>
              </body>
            </body>
          </body>
        </body>
      <body name="r_hip_pitch_mount" pos="0.050000 0.000000 0.000000" quat="0.7071068967259818 0.0 0.7071066656470943 -0.0">
        <inertial pos="0.000000 0.000000 0.000000" quat="1.0 0.0 0.0 0.0" mass="0.001000" diaginertia="2e-08 2e-08 2e-08" />
        <body name="r_hip_pitch" pos="0.000000 0.000000 0.000000" quat="1.0 0.0 0.0 0.0">
          <inertial pos="0.000000 -0.012000 0.000000" quat="1.0 0.0 0.0 0.0" mass="0.065000" diaginertia="1.797e-05 1.066e-05 1.611e-05" />
          <geom name="r_hip_pitch_collision" pos="0.000000 -0.012000 0.000000" quat="1.0 0.0 0.0 0.0" type="box" size="0.01425 0.02325 0.017" class="collision" />
          <geom name="r_hip_pitch_visual" pos="0.000000 0.000000 0.000000" quat="1.0 0.0 0.0 0.0" material="motor_gray" type="mesh" mesh="XL-430_new_coordinate_on_axis.STL" class="visual" />
          <body name="r_hip_roll" pos="-0.000000 0.000000 0.040000" quat="0.5000001633974483 -0.49999983660255165 0.4999999999999733 0.4999999999999733">
            <joint name="r_hip_pitch_joint" type="hinge" ref="0.0" class="motor" range="-3.14159 3.14159" axis="-1.000000 0.000000 0.000000" />
            <site name="r_hip_pitch_joint_site" pos="0 0 0" quat="1 0 0 0" />
            <inertial pos="0.000000 -0.012000 0.000000" quat="1.0 0.0 0.0 0.0" mass="0.065000" diaginertia="1.797e-05 1.066e-05 1.611e-05" />
            <geom name="r_hip_roll_collision" pos="0.000000 -0.012000 0.000000" quat="1.0 0.0 0.0 0.0" type="box" size="0.01425 0.02325 0.017" class="collision" />
            <geom name="r_hip_roll_visual" pos="0.000000 0.000000 0.000000" quat="1.0 0.0 0.0 0.0" material="motor_gray" type="mesh" mesh="XL-430_new_coordinate_on_axis.STL" class="visual" />
            <body name="r_hip_roll_joint_frame" pos="0.000000 0.000000 0.000000" quat="1.0 0.0 0.0 0.0">
              <joint name="r_hip_roll_joint" type="hinge" ref="0.0" class="motor" range="-3.14159 3.14159" axis="0.000000 0.000000 1.000000" />
              <site name="r_hip_roll_joint_site" pos="0 0 0" quat="1 0 0 0" />
              <inertial pos="0.000000 0.000000 0.000000" quat="1.0 0.0 0.0 0.0" mass="0.001000" diaginertia="2e-08 2e-08 2e-08" />
              <body name="r_hip_thigh_joint_frame" pos="-0.000000 -0.060000 0.000000" quat="1.0 0.0 0.0 0.0">
                <joint name="r_hip_thigh_joint" type="hinge" ref="0.0" class="motor" range="-3.14159 3.14159" axis="0.000000 0.000000 1.000000" />
                <site name="r_hip_thigh_joint_site" pos="0 0 0" quat="1 0 0 0" />
                <inertial pos="0.000000 0.000000 0.000000" quat="1.0 0.0 0.0 0.0" mass="0.001000" diaginertia="2e-08 2e-08 2e-08" />
                <body name="r_hip_thigh" pos="-0.000000 0.000000 0.000000" quat="0.7071068967259818 0.7071066656470943 0.0 0.0">
                  <inertial pos="0.000000 -0.012000 0.000000" quat="1.0 0.0 0.0 0.0" mass="0.065000" diaginertia="1.797e-05 1.066e-05 1.611e-05" />
                  <geom name="r_hip_thigh_collision" pos="0.000000 -0.012000 0.000000" quat="1.0 0.0 0.0 0.0" type="box" size="0.01425 0.02325 0.017" class="collision" />
                  <geom name="r_hip_thigh_visual" pos="0.000000 0.000000 0.000000" quat="1.0 0.0 0.0 0.0" material="motor_gray" type="mesh" mesh="XL-430_new_coordinate_on_axis.STL" class="visual" />
                  <body name="r_hip_calf_joint_frame" pos="-0.000000 0.000000 0.040000" quat="1.0 0.0 0.0 0.0">
                    <joint name="r_hip_calf_joint" type="hinge" ref="0.0" class="motor" range="-3.14159 3.14159" axis="0.000000 0.000000 1.000000" />
                    <site name="r_hip_calf_joint_site" pos="0 0 0" quat="1 0 0 0" />
                    <inertial pos="0.000000 0.000000 0.000000" quat="1.0 0.0 0.0 0.0" mass="0.001000" diaginertia="2e-08 2e-08 2e-08" />
                    <body name="r_hip_calf" pos="-0.000000 0.000000 0.000000" quat="0.5000001633974483 -0.4999999999999733 -0.49999983660255165 0.4999999999999733">
                      <inertial pos="0.000000 -0.012000 0.000000" quat="1.0 0.0 0.0 0.0" mass="0.065000" diaginertia="1.797e-05 1.066e-05 1.611e-05" />
                      <geom name="r_hip_calf_collision" pos="0.000000 -0.012000 0.000000" quat="1.0 0.0 0.0 0.0" type="box" size="0.01425 0.02325 0.017" class="collision" />
                      <geom name="r_hip_calf_visual" pos="0.000000 0.000000 0.000000" quat="1.0 0.0 0.0 0.0" material="motor_gray" type="mesh" mesh="XL-430_new_coordinate_on_axis.STL" class="visual" />
                      <body name="r_ankle_pitch_joint_frame" pos="-0.000000 -0.100000 0.000000" quat="1.0 0.0 0.0 0.0">
                        <joint name="r_ankle_pitch_joint" type="hinge" ref="0.0" class="motor" range="-3.14159 3.14159" axis="0.000000 0.000000 1.000000" />
                        <site name="r_ankle_pitch_joint_site" pos="0 0 0" quat="1 0 0 0" />
                        <inertial pos="0.000000 0.000000 0.000000" quat="1.0 0.0 0.0 0.0" mass="0.001000" diaginertia="2e-08 2e-08 2e-08" />
                        <body name="r_ankle_pitch" pos="-0.000000 0.000000 0.000000" quat="-1.7320510330969933e-07 -0.0 0.0 -0.999999999999985">
                          <inertial pos="0.000000 -0.012000 0.000000" quat="1.0 0.0 0.0 0.0" mass="0.065000" diaginertia="1.797e-05 1.066e-05 1.611e-05" />
                          <geom name="r_ankle_pitch_collision" pos="0.000000 -0.012000 0.000000" quat="1.0 0.0 0.0 0.0" type="box" size="0.01425 0.02325 0.017" class="collision" />
                          <geom name="r_ankle_pitch_visual" pos="0.000000 0.000000 0.000000" quat="1.0 0.0 0.0 0.0" material="motor_gray" type="mesh" mesh="XL-430_new_coordinate_on_axis.STL" class="visual" />
                          <body name="r_ankle_roll_joint_frame" pos="0.040000 0.000000 0.000000" quat="1.0 0.0 0.0 0.0">
                            <joint name="r_ankle_roll_joint" type="hinge" ref="0.0" class="motor" range="-3.14159 3.14159" axis="0.000000 0.000000 1.000000" />
                            <site name="r_ankle_roll_joint_site" pos="0 0 0" quat="1 0 0 0" />
                            <inertial pos="0.000000 0.000000 0.000000" quat="1.0 0.0 0.0 0.0" mass="0.001000" diaginertia="2e-08 2e-08 2e-08" />
                            <body name="r_ankle_roll" pos="-0.000000 0.000000 0.000000" quat="0.7071068967259818 0.0 -0.7071066656470943 0.0">
                              <inertial pos="0.000000 -0.012000 0.000000" quat="1.0 0.0 0.0 0.0" mass="0.065000" diaginertia="1.797e-05 1.066e-05 1.611e-05" />
                              <geom name="r_ankle_roll_collision" pos="0.000000 -0.012000 0.000000" quat="1.0 0.0 0.0 0.0" type="box" size="0.01425 0.02325 0.017" class="collision" />
                              <geom name="r_ankle_roll_visual" pos="0.000000 0.000000 0.000000" quat="1.0 0.0 0.0 0.0" material="motor_gray" type="mesh" mesh="XL-430_new_coordinate_on_axis.STL" class="visual" />
                              <body name="r_foot" pos="-0.000000 0.035000 0.040000" quat="0.5000001633974483 0.49999983660255165 0.4999999999999733 -0.4999999999999733">
                                <inertial pos="0.000000 0.000000 0.000000" quat="1.0 0.0 0.0 0.0" mass="0.050000" diaginertia="1.542e-05 4.208e-05 5.667e-05" />
                                <geom name="r_foot_collision" pos="0.000000 0.000000 0.000000" quat="1.0 0.0 0.0 0.0" type="box" size="0.05 0.03 0.005" class="collision" />
                                <geom name="r_foot_visual" pos="0.000000 0.000000 0.000000" quat="1.0 0.0 0.0 0.0" material="motor_gray" type="box" size="0.05 0.03 0.005" class="visual" />
                                </body>
                              </body>
                            </body>
                          </body>
                        </body>
                      </body>
                    </body>
                  </body>
                </body>
              </body>
            </body>
          </body>
        </body>
      <body name="trunk_link" pos="0.000000 0.000000 0.110000" quat="1.0 0.0 0.0 0.0">
        <joint name="base_to_trunk" type="hinge" ref="0.0" class="motor" range="-3.14159 3.14159" axis="0.000000 0.000000 1.000000" />
        <site name="base_to_trunk_site" pos="0 0 0" quat="1 0 0 0" />
        <inertial pos="0.000000 0.000000 0.000000" quat="1.0 0.0 0.0 0.0" mass="0.300000" diaginertia="0.000565 0.000685 0.000125" />
        <geom name="trunk_link_collision" pos="0.000000 0.000000 0.000000" quat="1.0 0.0 0.0 0.0" type="box" size="0.035 0.005 0.075" class="collision" />
        <geom name="trunk_link_visual" pos="0.000000 0.000000 0.000000" quat="1.0 0.0 0.0 0.0" material="motor_gray" type="box" size="0.035 0.005 0.075" class="visual" />
        </body>
      <site name="base_motor_link_site" pos="0 0 0" quat="1 0 0 0" />
      <camera name="front_camera" mode="track" fovy="90.0" quat="4.329780281177467e-17 4.329780281177466e-17 0.7071067811865475 0.7071067811865476" pos="0.0 2.0 0.5" />
      <camera name="side_camera" mode="track" fovy="90.0" quat="-0.5 -0.4999999999999999 0.5 0.5000000000000001" pos="-2.0 0.0 0.5" />
      </body>
    </worldbody>
  <actuator>
    <motor name="l_hip_pitch_joint_ctrl" joint="l_hip_pitch_joint" class="motor" />
    <motor name="l_hip_roll_joint_ctrl" joint="l_hip_roll_joint" class="motor" />
    <motor name="l_hip_thigh_joint_ctrl" joint="l_hip_thigh_joint" class="motor" />
    <motor name="l_hip_calf_joint_ctrl" joint="l_hip_calf_joint" class="motor" />
    <motor name="l_ankle_pitch_joint_ctrl" joint="l_ankle_pitch_joint" class="motor" />
    <motor name="l_ankle_roll_joint_ctrl" joint="l_ankle_roll_joint" class="motor" />
    <motor name="r_hip_pitch_joint_ctrl" joint="r_hip_pitch_joint" class="motor" />
    <motor name="r_hip_roll_joint_ctrl" joint="r_hip_roll_joint" class="motor" />
    <motor name="r_hip_thigh_joint_ctrl" joint="r_hip_thigh_joint" class="motor" />
    <motor name="r_hip_calf_joint_ctrl" joint="r_hip_calf_joint" class="motor" />
    <motor name="r_ankle_pitch_joint_ctrl" joint="r_ankle_pitch_joint" class="motor" />
    <motor name="r_ankle_roll_joint_ctrl" joint="r_ankle_roll_joint" class="motor" />
    <motor name="base_to_trunk_ctrl" joint="base_to_trunk" class="motor" />
    </actuator>
  <contact>
    <exclude body1="l_hip_pitch" body2="l_hip_roll" />
    <exclude body1="l_ankle_roll" body2="l_foot" />
    <exclude body1="r_hip_pitch" body2="r_hip_roll" />
    <exclude body1="r_ankle_roll" body2="r_foot" />
    <exclude body1="base_motor_link" body2="trunk_link" />
    </contact>
  <sensor>
    <framepos name="l_hip_pitch_joint_site_pos" objtype="site" objname="l_hip_pitch_joint_site" />
    <framequat name="l_hip_pitch_joint_site_quat" objtype="site" objname="l_hip_pitch_joint_site" />
    <framelinvel name="l_hip_pitch_joint_site_linvel" objtype="site" objname="l_hip_pitch_joint_site" />
    <frameangvel name="l_hip_pitch_joint_site_angvel" objtype="site" objname="l_hip_pitch_joint_site" />
    <velocimeter name="l_hip_pitch_joint_site_vel" site="l_hip_pitch_joint_site" />
    </sensor>
  </mujoco>
