<mujoco model="3">
  <default>
    <default class="robot">
      <default class="motor">
        <joint />
        <motor />
        </default>
      <default class="visual">
        <geom material="visualgeom" contype="0" conaffinity="0" group="2" />
        </default>
      <default class="collision">
        <geom material="collision_material" condim="3" contype="0" conaffinity="1" priority="1" group="1" solref="0.005 1" solimp="0.99 0.999 1e-05" friction="1 0.01 0.01" />
        </default>
      </default>
    </default>
  <compiler angle="radian" meshdir="meshes/" />
  <asset>
    <material name="visualgeom" rgba="1 0.949019607843137 0.898039215686275 1" />
    <material name="default_material" rgba="0.7 0.7 0.7 1" />
    <material name="collision_material" rgba="0.89804 0.91765 0.92941 1.0" />
    <mesh name="base_link.STL" file="base_link.STL" />
    <mesh name="r_hip_pitch_link.STL" file="r_hip_pitch_link.STL" />
    <mesh name="r_hip_roll_link.STL" file="r_hip_roll_link.STL" />
    <mesh name="r_hip_thigh_link.STL" file="r_hip_thigh_link.STL" />
    <mesh name="r_hip_calf_link.STL" file="r_hip_calf_link.STL" />
    <mesh name="r_ankle_pitch_link.STL" file="r_ankle_pitch_link.STL" />
    <mesh name="r_ankle_roll_link.STL" file="r_ankle_roll_link.STL" />
    <mesh name="l_hip_pitch_link.STL" file="l_hip_pitch_link.STL" />
    <mesh name="l_hip_roll_link.STL" file="l_hip_roll_link.STL" />
    <mesh name="l_hip_thigh_link.STL" file="l_hip_thigh_link.STL" />
    <mesh name="l_hip_calf_link.STL" file="l_hip_calf_link.STL" />
    <mesh name="l_ankle_pitch_link.STL" file="l_ankle_pitch_link.STL" />
    <mesh name="l_ankle_roll_link.STL" file="l_ankle_roll_link.STL" />
    <mesh name="waist_yaw_link.STL" file="waist_yaw_link.STL" />
    </asset>
  <worldbody>
    <body name="base_link" pos="0.00000000 0.00000000 0.20900000" quat="1 0 0 0" childclass="robot">
      <freejoint name="floating_base" />
      <geom name="base_link_collision" pos="0 0 0" quat="1.0 0.0 0.0 0.0" type="mesh" mesh="base_link.STL" class="collision" />
      <geom name="base_link_visual" pos="0 0 0" quat="1.0 0.0 0.0 0.0" material="visualgeom" type="mesh" mesh="base_link.STL" class="visual" />
      <body name="r_hip_pitch_link" pos="0 0.03775 -0.209" quat="2.609984271978568e-30 -1.6155445744325867e-15 1.0 -1.6155445744325867e-15">
        <joint name="r_hip_pitch_joint" type="hinge" ref="0.0" class="motor" range="-3.142 3.142" axis="0 1 0" />
        <site name="r_hip_pitch_joint_site" pos="0 0 0" quat="1 0 0 0" />
        <inertial pos="0.000512585106856932 -0.0377390460968998 -0.0116725900125635" quat="1.0 0.0 0.0 0.0" mass="0.0438786463015405" diaginertia="9.966209816454e-06 1.10068546473359e-05 6.38513107006193e-06" />
        <geom name="r_hip_pitch_link_collision" pos="0 0 0" quat="1.0 0.0 0.0 0.0" type="mesh" mesh="r_hip_pitch_link.STL" class="collision" />
        <geom name="r_hip_pitch_link_visual" pos="0 0 0" quat="1.0 0.0 0.0 0.0" material="visualgeom" type="mesh" mesh="r_hip_pitch_link.STL" class="visual" />
        <body name="r_hip_roll_link" pos="0 -0.03775 0" quat="1.0 0.0 0.0 0.0">
          <joint name="r_hip_roll_joint" type="hinge" ref="0.0" class="motor" range="-3.142 3.142" axis="-1 0 0" />
          <site name="r_hip_roll_joint_site" pos="0 0 0" quat="1 0 0 0" />
          <inertial pos="-0.0116725900125634 1.09539031014981E-05 -0.0592625851068567" quat="1.0 0.0 0.0 0.0" mass="0.0438786463015405" diaginertia="6.38513107006192e-06 1.10068546473358e-05 9.96620981645398e-06" />
          <geom name="r_hip_roll_link_collision" pos="0 0 0" quat="1.0 0.0 0.0 0.0" type="mesh" mesh="r_hip_roll_link.STL" class="collision" />
          <geom name="r_hip_roll_link_visual" pos="0 0 0" quat="1.0 0.0 0.0 0.0" material="visualgeom" type="mesh" mesh="r_hip_roll_link.STL" class="visual" />
          <body name="r_hip_thigh_link" pos="0 0 -0.0587499999999997" quat="1.0 0.0 0.0 0.0">
            <joint name="r_hip_thigh_joint" type="hinge" ref="0.0" class="motor" range="-3.142 3.142" axis="0 0 1" />
            <site name="r_hip_thigh_joint_site" pos="0 0 0" quat="1 0 0 0" />
            <inertial pos="1.0953903100219E-05 -0.000512585106857445 -0.0464225900125635" quat="1.0 0.0 0.0 0.0" mass="0.0438786463015405" diaginertia="1.10068546473359e-05 9.96620981645401e-06 6.38513107006194e-06" />
            <geom name="r_hip_thigh_link_collision" pos="0 0 0" quat="1.0 0.0 0.0 0.0" type="mesh" mesh="r_hip_thigh_link.STL" class="collision" />
            <geom name="r_hip_thigh_link_visual" pos="0 0 0" quat="1.0 0.0 0.0 0.0" material="visualgeom" type="mesh" mesh="r_hip_thigh_link.STL" class="visual" />
            <body name="r_hip_calf_link" pos="0 0 -0.03475" quat="1.0 0.0 0.0 0.0">
              <joint name="r_hip_calf_joint" type="hinge" ref="0.0" class="motor" range="-3.142 3.142" axis="0 1 0" />
              <site name="r_hip_calf_joint_site" pos="0 0 0" quat="1 0 0 0" />
              <inertial pos="-1.09539031002066E-05 -0.000512585106856929 -0.103827409987437" quat="1.0 0.0 0.0 0.0" mass="0.0438786463015405" diaginertia="1.10068546473359e-05 9.96620981645399e-06 6.38513107006194e-06" />
              <geom name="r_hip_calf_link_collision" pos="0 0 0" quat="1.0 0.0 0.0 0.0" type="mesh" mesh="r_hip_calf_link.STL" class="collision" />
              <geom name="r_hip_calf_link_visual" pos="0 0 0" quat="1.0 0.0 0.0 0.0" material="visualgeom" type="mesh" mesh="r_hip_calf_link.STL" class="visual" />
              <body name="r_ankle_pitch_link" pos="0 0 -0.1155" quat="1.0 0.0 0.0 0.0">
                <joint name="r_ankle _pitch_joint" type="hinge" ref="0.0" class="motor" range="-3.142 3.142" axis="0 1 0" />
                <site name="r_ankle _pitch_joint_site" pos="0 0 0" quat="1 0 0 0" />
                <inertial pos="-0.037237414893143 -1.09539031002194E-05 0.0116725900125634" quat="1.0 0.0 0.0 0.0" mass="0.0438786463015405" diaginertia="9.96620981645399e-06 1.10068546473359e-05 6.38513107006194e-06" />
                <geom name="r_ankle_pitch_link_collision" pos="0 0 0" quat="1.0 0.0 0.0 0.0" type="mesh" mesh="r_ankle_pitch_link.STL" class="collision" />
                <geom name="r_ankle_pitch_link_visual" pos="0 0 0" quat="1.0 0.0 0.0 0.0" material="visualgeom" type="mesh" mesh="r_ankle_pitch_link.STL" class="visual" />
                <body name="r_ankle_roll_link" pos="-0.03775 0 0" quat="1.0 0.0 0.0 0.0">
                  <joint name="r_ankle_roll_joint" type="hinge" ref="0.0" class="motor" range="-3.142 3.142" axis="-1 0 0" />
                  <site name="r_ankle_roll_joint_site" pos="0 0 0" quat="1 0 0 0" />
                  <inertial pos="0.0395 -0.00262871663161335 -0.0261768335109488" quat="1.0 0.0 0.0 0.0" mass="0.168105015619337" diaginertia="5.68510292905988e-05 0.000155703689867648 0.000207033359916456" />
                  <geom name="r_ankle_roll_link_collision" pos="0 0 0" quat="1.0 0.0 0.0 0.0" type="mesh" mesh="r_ankle_roll_link.STL" class="collision" />
                  <geom name="r_ankle_roll_link_visual" pos="0 0 0" quat="1.0 0.0 0.0 0.0" material="visualgeom" type="mesh" mesh="r_ankle_roll_link.STL" class="visual" />
                  </body>
                </body>
              </body>
            </body>
          </body>
        </body>
      <body name="l_hip_pitch_link" pos="0 0.11325 -0.209000000000001" quat="2.609984271978568e-30 -1.6155445744325867e-15 1.0 -1.6155445744325867e-15">
        <joint name="l_hip_pitch_joint" type="hinge" ref="0.0" class="motor" range="-3.142 3.142" axis="0 -1 0" />
        <site name="l_hip_pitch_joint_site" pos="0 0 0" quat="1 0 0 0" />
        <inertial pos="0.000512585106856032 0.0377609539031015 -0.0116725900125656" quat="1.0 0.0 0.0 0.0" mass="0.0438786463015405" diaginertia="9.966209816454e-06 1.10068546473359e-05 6.38513107006194e-06" />
        <geom name="l_hip_pitch_link_collision" pos="0 0 0" quat="1.0 0.0 0.0 0.0" type="mesh" mesh="l_hip_pitch_link.STL" class="collision" />
        <geom name="l_hip_pitch_link_visual" pos="0 0 0" quat="1.0 0.0 0.0 0.0" material="visualgeom" type="mesh" mesh="l_hip_pitch_link.STL" class="visual" />
        <body name="l_hip_roll_link" pos="0 0.0377500000000015 0" quat="1.0 0.0 0.0 0.0">
          <joint name="l_hip_roll_joint" type="hinge" ref="0.0" class="motor" range="-3.142 3.142" axis="-1 0 0" />
          <site name="l_hip_roll_joint_site" pos="0 0 0" quat="1 0 0 0" />
          <inertial pos="-0.0116725900125597 1.09539030993255E-05 -0.0592625851068558" quat="1.0 0.0 0.0 0.0" mass="0.0438786463015405" diaginertia="6.38513107006194e-06 1.10068546473358e-05 9.96620981645398e-06" />
          <geom name="l_hip_roll_link_collision" pos="0 0 0" quat="1.0 0.0 0.0 0.0" type="mesh" mesh="l_hip_roll_link.STL" class="collision" />
          <geom name="l_hip_roll_link_visual" pos="0 0 0" quat="1.0 0.0 0.0 0.0" material="visualgeom" type="mesh" mesh="l_hip_roll_link.STL" class="visual" />
          <body name="l_hip_thigh_link" pos="0 0 -0.0587499999999989" quat="1.0 0.0 0.0 0.0">
            <joint name="l_hip_thigh_joint" type="hinge" ref="0.0" class="motor" range="-3.142 3.142" axis="0 0 1" />
            <site name="l_hip_thigh_joint_site" pos="0 0 0" quat="1 0 0 0" />
            <inertial pos="-1.09539031000581E-05 0.000512585106856783 -0.0464225900125635" quat="1.0 0.0 0.0 0.0" mass="0.0438786463015405" diaginertia="1.10068546473358e-05 9.96620981645398e-06 6.38513107006193e-06" />
            <geom name="l_hip_thigh_link_collision" pos="0 0 0" quat="1.0 0.0 0.0 0.0" type="mesh" mesh="l_hip_thigh_link.STL" class="collision" />
            <geom name="l_hip_thigh_link_visual" pos="0 0 0" quat="1.0 0.0 0.0 0.0" material="visualgeom" type="mesh" mesh="l_hip_thigh_link.STL" class="visual" />
            <body name="l_hip_calf_link" pos="0 0 -0.03475" quat="1.0 0.0 0.0 0.0">
              <joint name="l_hip_calf_joint" type="hinge" ref="0.0" class="motor" range="-3.142 3.142" axis="0 -1 0" />
              <site name="l_hip_calf_joint_site" pos="0 0 0" quat="1 0 0 0" />
              <inertial pos="1.09539031001142E-05 0.000512585106856728 -0.103827409987437" quat="1.0 0.0 0.0 0.0" mass="0.0438786463015405" diaginertia="1.10068546473359e-05 9.96620981645399e-06 6.38513107006194e-06" />
              <geom name="l_hip_calf_link_collision" pos="0 0 0" quat="1.0 0.0 0.0 0.0" type="mesh" mesh="l_hip_calf_link.STL" class="collision" />
              <geom name="l_hip_calf_link_visual" pos="0 0 0" quat="1.0 0.0 0.0 0.0" material="visualgeom" type="mesh" mesh="l_hip_calf_link.STL" class="visual" />
              <body name="l_ankle_pitch_link" pos="0 0 -0.1155" quat="1.0 0.0 0.0 0.0">
                <joint name="l_ankle_pitch_joint" type="hinge" ref="0.0" class="motor" range="-3.142 3.142" axis="0 -1 0" />
                <site name="l_ankle_pitch_joint_site" pos="0 0 0" quat="1 0 0 0" />
                <inertial pos="-0.0372374148931425 -1.09539031001027E-05 0.0116725900125634" quat="1.0 0.0 0.0 0.0" mass="0.0438786463015405" diaginertia="9.96620981645399e-06 1.10068546473359e-05 6.38513107006193e-06" />
                <geom name="l_ankle_pitch_link_collision" pos="0 0 0" quat="1.0 0.0 0.0 0.0" type="mesh" mesh="l_ankle_pitch_link.STL" class="collision" />
                <geom name="l_ankle_pitch_link_visual" pos="0 0 0" quat="1.0 0.0 0.0 0.0" material="visualgeom" type="mesh" mesh="l_ankle_pitch_link.STL" class="visual" />
                <body name="l_ankle_roll_link" pos="-0.0377499999999995 0 0" quat="1.0 0.0 0.0 0.0">
                  <joint name="l_ankle_roll_joint" type="hinge" ref="0.0" class="motor" range="-3.142 3.142" axis="-1 0 0" />
                  <site name="l_ankle_roll_joint_site" pos="0 0 0" quat="1 0 0 0" />
                  <inertial pos="0.0394999999999984 1.11022302462516E-16 -0.0263084922370927" quat="1.0 0.0 0.0 0.0" mass="0.168105015619337" diaginertia="5.68510292905987e-05 0.000155180783823683 0.000207556265960421" />
                  <geom name="l_ankle_roll_link_collision" pos="0 0 0" quat="1.0 0.0 0.0 0.0" type="mesh" mesh="l_ankle_roll_link.STL" class="collision" />
                  <geom name="l_ankle_roll_link_visual" pos="0 0 0" quat="1.0 0.0 0.0 0.0" material="visualgeom" type="mesh" mesh="l_ankle_roll_link.STL" class="visual" />
                  </body>
                </body>
              </body>
            </body>
          </body>
        </body>
      <body name="waist_yaw_link" pos="0 0.0754999999999976 -0.209000000000003" quat="1.0860612277657784e-29 -1.6155445744325867e-15 1.0 -6.722570487708307e-15">
        <joint name="waist_yaw_joint" type="hinge" ref="0.0" class="motor" range="-3.142 3.142" axis="0 0 -1" />
        <site name="waist_yaw_joint_site" pos="0 0 0" quat="1 0 0 0" />
        <inertial pos="-2.25280917660021E-16 -1.38777878078145E-17 0.0949999999999975" quat="1.0 0.0 0.0 0.0" mass="0.232848" diaginertia="0.000475398000000001 0.000381016944000001 9.57781440000002e-05" />
        <geom name="waist_yaw_link_collision" pos="0 0 0" quat="1.0 0.0 0.0 0.0" type="mesh" mesh="waist_yaw_link.STL" class="collision" />
        <geom name="waist_yaw_link_visual" pos="0 0 0" quat="1.0 0.0 0.0 0.0" material="visualgeom" type="mesh" mesh="waist_yaw_link.STL" class="visual" />
        </body>
      <site name="base_link_site" pos="0 0 0" quat="1 0 0 0" />
      <camera name="front_camera" mode="track" fovy="90.0" quat="4.329780281177467e-17 4.329780281177466e-17 0.7071067811865475 0.7071067811865476" pos="0.0 2.0 0.5" />
      <camera name="side_camera" mode="track" fovy="90.0" quat="-0.5 -0.4999999999999999 0.5 0.5000000000000001" pos="-2.0 0.0 0.5" />
      </body>
    </worldbody>
  <actuator>
    <motor name="r_hip_pitch_joint_ctrl" joint="r_hip_pitch_joint" class="motor" />
    <motor name="r_hip_roll_joint_ctrl" joint="r_hip_roll_joint" class="motor" />
    <motor name="r_hip_thigh_joint_ctrl" joint="r_hip_thigh_joint" class="motor" />
    <motor name="r_hip_calf_joint_ctrl" joint="r_hip_calf_joint" class="motor" />
    <motor name="r_ankle _pitch_joint_ctrl" joint="r_ankle _pitch_joint" class="motor" />
    <motor name="r_ankle_roll_joint_ctrl" joint="r_ankle_roll_joint" class="motor" />
    <motor name="l_hip_pitch_joint_ctrl" joint="l_hip_pitch_joint" class="motor" />
    <motor name="l_hip_roll_joint_ctrl" joint="l_hip_roll_joint" class="motor" />
    <motor name="l_hip_thigh_joint_ctrl" joint="l_hip_thigh_joint" class="motor" />
    <motor name="l_hip_calf_joint_ctrl" joint="l_hip_calf_joint" class="motor" />
    <motor name="l_ankle_pitch_joint_ctrl" joint="l_ankle_pitch_joint" class="motor" />
    <motor name="l_ankle_roll_joint_ctrl" joint="l_ankle_roll_joint" class="motor" />
    <motor name="waist_yaw_joint_ctrl" joint="waist_yaw_joint" class="motor" />
    </actuator>
  <contact>
    <exclude body1="base_link" body2="r_hip_pitch_link" />
    <exclude body1="r_hip_pitch_link" body2="r_hip_roll_link" />
    <exclude body1="r_hip_roll_link" body2="r_hip_thigh_link" />
    <exclude body1="r_hip_thigh_link" body2="r_hip_calf_link" />
    <exclude body1="r_hip_calf_link" body2="r_ankle_pitch_link" />
    <exclude body1="r_ankle_pitch_link" body2="r_ankle_roll_link" />
    <exclude body1="base_link" body2="l_hip_pitch_link" />
    <exclude body1="l_hip_pitch_link" body2="l_hip_roll_link" />
    <exclude body1="l_hip_roll_link" body2="l_hip_thigh_link" />
    <exclude body1="l_hip_thigh_link" body2="l_hip_calf_link" />
    <exclude body1="l_hip_calf_link" body2="l_ankle_pitch_link" />
    <exclude body1="l_ankle_pitch_link" body2="l_ankle_roll_link" />
    <exclude body1="base_link" body2="waist_yaw_link" />
    </contact>
  <sensor>
    <framepos name="r_hip_pitch_joint_site_pos" objtype="site" objname="r_hip_pitch_joint_site" />
    <framequat name="r_hip_pitch_joint_site_quat" objtype="site" objname="r_hip_pitch_joint_site" />
    <framelinvel name="r_hip_pitch_joint_site_linvel" objtype="site" objname="r_hip_pitch_joint_site" />
    <frameangvel name="r_hip_pitch_joint_site_angvel" objtype="site" objname="r_hip_pitch_joint_site" />
    <velocimeter name="r_hip_pitch_joint_site_vel" site="r_hip_pitch_joint_site" />
    </sensor>
  </mujoco>
